ERROR 2014-05-12 16:44:11,046 views 8752 10224 Traceback (most recent call last):
  File "D:\work\iqfight\iqfight\iqfight\iqfight_app\views.py", line 86, in get_games
    games = get_games_list()
  File "D:\work\iqfight\iqfight\iqfight\iqfight_app\views.py", line 19, in get_games_list
    return Game.objects.filter(is_active=True).values('name','id','players_to_start')
  File "C:\Python27\lib\site-packages\django\db\models\query.py", line 525, in values
    return self._clone(klass=ValuesQuerySet, setup=True, _fields=fields)
  File "C:\Python27\lib\site-packages\django\db\models\query.py", line 849, in _clone
    c._setup_query()
  File "C:\Python27\lib\site-packages\django\db\models\query.py", line 992, in _setup_query
    self.query.add_fields(self.field_names, True)
  File "C:\Python27\lib\site-packages\django\db\models\sql\query.py", line 1554, in add_fields
    "Choices are: %s" % (name, ", ".join(names)))
FieldError: Cannot resolve keyword 'players_to_start' into field. Choices are: answered, created, current_question, id, is_active, max_num_of_players, name, num_of_players, players, question_started, questions

ERROR 2014-05-12 17:00:07,369 views 6440 5216 Traceback (most recent call last):
  File "D:\work\iqfight\iqfight\iqfight\iqfight_app\views.py", line 63, in register
    if passowrd1 != password:
NameError: global name 'passowrd1' is not defined

ERROR 2014-05-12 17:06:50,595 views 6168 11076 Traceback (most recent call last):
  File "D:\work\iqfight\iqfight\iqfight\iqfight_app\views.py", line 112, in open_game
    pg,created = PlayerGames.objects.get_or_create(player=player,game=game,is_active=True)
  File "C:\Python27\lib\site-packages\django\db\models\manager.py", line 154, in get_or_create
    return self.get_queryset().get_or_create(**kwargs)
  File "C:\Python27\lib\site-packages\django\db\models\query.py", line 373, in get_or_create
    return self.get(**lookup), False
  File "C:\Python27\lib\site-packages\django\db\models\query.py", line 298, in get
    clone = self.filter(*args, **kwargs)
  File "C:\Python27\lib\site-packages\django\db\models\query.py", line 590, in filter
    return self._filter_or_exclude(False, *args, **kwargs)
  File "C:\Python27\lib\site-packages\django\db\models\query.py", line 608, in _filter_or_exclude
    clone.query.add_q(Q(*args, **kwargs))
  File "C:\Python27\lib\site-packages\django\db\models\sql\query.py", line 1198, in add_q
    clause = self._add_q(where_part, used_aliases)
  File "C:\Python27\lib\site-packages\django\db\models\sql\query.py", line 1234, in _add_q
    current_negated=current_negated)
  File "C:\Python27\lib\site-packages\django\db\models\sql\query.py", line 1100, in build_filter
    allow_explicit_fk=True)
  File "C:\Python27\lib\site-packages\django\db\models\sql\query.py", line 1357, in setup_joins
    names, opts, allow_many, allow_explicit_fk)
  File "C:\Python27\lib\site-packages\django\db\models\sql\query.py", line 1277, in names_to_path
    "Choices are: %s" % (name, ", ".join(available)))
FieldError: Cannot resolve keyword 'is_active' into field. Choices are: ended, game, id, is_current, player, points, started

ERROR 2014-05-12 17:08:38,414 views 8484 7224 Traceback (most recent call last):
  File "D:\work\iqfight\iqfight\iqfight\iqfight_app\views.py", line 131, in refresh_game
    players = PlayerGames.objects.select_related().filter(game=game,is_active=True,ended__isnull=True)
  File "C:\Python27\lib\site-packages\django\db\models\query.py", line 590, in filter
    return self._filter_or_exclude(False, *args, **kwargs)
  File "C:\Python27\lib\site-packages\django\db\models\query.py", line 608, in _filter_or_exclude
    clone.query.add_q(Q(*args, **kwargs))
  File "C:\Python27\lib\site-packages\django\db\models\sql\query.py", line 1198, in add_q
    clause = self._add_q(where_part, used_aliases)
  File "C:\Python27\lib\site-packages\django\db\models\sql\query.py", line 1234, in _add_q
    current_negated=current_negated)
  File "C:\Python27\lib\site-packages\django\db\models\sql\query.py", line 1100, in build_filter
    allow_explicit_fk=True)
  File "C:\Python27\lib\site-packages\django\db\models\sql\query.py", line 1357, in setup_joins
    names, opts, allow_many, allow_explicit_fk)
  File "C:\Python27\lib\site-packages\django\db\models\sql\query.py", line 1277, in names_to_path
    "Choices are: %s" % (name, ", ".join(available)))
FieldError: Cannot resolve keyword 'is_active' into field. Choices are: ended, game, id, is_current, player, points, started

ERROR 2014-05-12 17:09:08,694 views 8000 6516 Traceback (most recent call last):
  File "D:\work\iqfight\iqfight\iqfight\iqfight_app\views.py", line 132, in refresh_game
    users = [el.user.username for el in players]
AttributeError: 'PlayerGames' object has no attribute 'user'

ERROR 2014-05-12 17:10:14,529 views 10980 10312 Traceback (most recent call last):
  File "D:\work\iqfight\iqfight\iqfight\iqfight_app\views.py", line 62, in register
    username=data['username']
  File "C:\Python27\lib\site-packages\django\utils\datastructures.py", line 301, in __getitem__
    raise MultiValueDictKeyError(repr(key))
MultiValueDictKeyError: "'username'"

ERROR 2014-05-12 17:10:47,354 views 10980 5056 Traceback (most recent call last):
  File "D:\work\iqfight\iqfight\iqfight\iqfight_app\views.py", line 62, in register
    username=data['username']
  File "C:\Python27\lib\site-packages\django\utils\datastructures.py", line 301, in __getitem__
    raise MultiValueDictKeyError(repr(key))
MultiValueDictKeyError: "'username'"

ERROR 2014-05-12 17:11:38,854 views 9332 5424 Traceback (most recent call last):
  File "D:\work\iqfight\iqfight\iqfight\iqfight_app\views.py", line 69, in register
    user = User.objects.create_user(username=username,email = username ,password = password)
  File "C:\Python27\lib\site-packages\django\contrib\auth\models.py", line 191, in create_user
    **extra_fields)
  File "C:\Python27\lib\site-packages\django\contrib\auth\models.py", line 186, in _create_user
    user.save(using=self._db)
  File "C:\Python27\lib\site-packages\django\db\models\base.py", line 545, in save
    force_update=force_update, update_fields=update_fields)
  File "C:\Python27\lib\site-packages\django\db\models\base.py", line 573, in save_base
    updated = self._save_table(raw, cls, force_insert, force_update, using, update_fields)
  File "C:\Python27\lib\site-packages\django\db\models\base.py", line 654, in _save_table
    result = self._do_insert(cls._base_manager, using, fields, update_pk, raw)
  File "C:\Python27\lib\site-packages\django\db\models\base.py", line 687, in _do_insert
    using=using, raw=raw)
  File "C:\Python27\lib\site-packages\django\db\models\manager.py", line 232, in _insert
    return insert_query(self.model, objs, fields, **kwargs)
  File "C:\Python27\lib\site-packages\django\db\models\query.py", line 1511, in insert_query
    return query.get_compiler(using=using).execute_sql(return_id)
  File "C:\Python27\lib\site-packages\django\db\models\sql\compiler.py", line 903, in execute_sql
    cursor.execute(sql, params)
  File "C:\Python27\lib\site-packages\django\db\backends\util.py", line 69, in execute
    return super(CursorDebugWrapper, self).execute(sql, params)
  File "C:\Python27\lib\site-packages\django\db\backends\util.py", line 53, in execute
    return self.cursor.execute(sql, params)
  File "C:\Python27\lib\site-packages\django\db\utils.py", line 99, in __exit__
    six.reraise(dj_exc_type, dj_exc_value, traceback)
  File "C:\Python27\lib\site-packages\django\db\backends\util.py", line 53, in execute
    return self.cursor.execute(sql, params)
  File "C:\Python27\lib\site-packages\django\db\backends\mysql\base.py", line 124, in execute
    return self.cursor.execute(query, args)
  File "C:\Python27\lib\site-packages\MySQLdb\cursors.py", line 174, in execute
    self.errorhandler(self, exc, value)
  File "C:\Python27\lib\site-packages\MySQLdb\connections.py", line 36, in defaulterrorhandler
    raise errorclass, errorvalue
IntegrityError: (1062, "Duplicate entry 'test1' for key 'username'")

ERROR 2014-05-12 17:12:45,190 views 3064 10808 Traceback (most recent call last):
  File "D:\work\iqfight\iqfight\iqfight\iqfight_app\views.py", line 41, in login_func
    user = authenticate(username=data['username'], password=data['password'])
  File "C:\Python27\lib\site-packages\django\utils\datastructures.py", line 301, in __getitem__
    raise MultiValueDictKeyError(repr(key))
MultiValueDictKeyError: "'username'"

ERROR 2014-05-12 17:41:35,380 base 10432 7352 Internal Server Error: /media/pictures/Q11/0.gif
Traceback (most recent call last):
  File "C:\Python27\lib\site-packages\django\core\handlers\base.py", line 90, in get_response
    response = middleware_method(request)
  File "C:\Python27\lib\site-packages\django\middleware\common.py", line 71, in process_request
    if (not urlresolvers.is_valid_path(request.path_info, urlconf) and
  File "C:\Python27\lib\site-packages\django\core\urlresolvers.py", line 592, in is_valid_path
    resolve(path, urlconf)
  File "C:\Python27\lib\site-packages\django\core\urlresolvers.py", line 472, in resolve
    return get_resolver(urlconf).resolve(path)
  File "C:\Python27\lib\site-packages\django\core\urlresolvers.py", line 333, in resolve
    for pattern in self.url_patterns:
  File "C:\Python27\lib\site-packages\django\core\urlresolvers.py", line 361, in url_patterns
    patterns = getattr(self.urlconf_module, "urlpatterns", self.urlconf_module)
  File "C:\Python27\lib\site-packages\django\core\urlresolvers.py", line 356, in urlconf_module
    self._urlconf_module = import_module(self.urlconf_name)
  File "C:\Python27\lib\site-packages\django\utils\importlib.py", line 40, in import_module
    __import__(name)
  File "D:\work\iqfight\iqfight\iqfight\urls.py", line 22, in <module>
    )+ static(settings.MEDIA_URL, document_root=settings.MEDIA_ROOT)
NameError: name 'settings' is not defined
